Traceback (most recent call last):
  File "c:\anaconda3\lib\site-packages\jupyter_cache\executors\utils.py", line 56, in single_nb_execution
    record_timing=False,
  File "c:\anaconda3\lib\site-packages\nbclient\client.py", line 1087, in execute
    return NotebookClient(nb=nb, resources=resources, km=km, **kwargs).execute()
  File "c:\anaconda3\lib\site-packages\nbclient\util.py", line 74, in wrapped
    return just_run(coro(*args, **kwargs))
  File "c:\anaconda3\lib\site-packages\nbclient\util.py", line 53, in just_run
    return loop.run_until_complete(coro)
  File "c:\anaconda3\lib\asyncio\base_events.py", line 587, in run_until_complete
    return future.result()
  File "c:\anaconda3\lib\site-packages\nbclient\client.py", line 541, in async_execute
    cell, index, execution_count=self.code_cells_executed + 1
  File "c:\anaconda3\lib\site-packages\nbclient\client.py", line 832, in async_execute_cell
    self._check_raise_for_error(cell, exec_reply)
  File "c:\anaconda3\lib\site-packages\nbclient\client.py", line 740, in _check_raise_for_error
    raise CellExecutionError.from_cell_and_msg(cell, exec_reply['content'])
nbclient.exceptions.CellExecutionError: An error occurred while executing the following cell:
------------------
p = Punto2d(100, 10, 3)
------------------

[1;31m---------------------------------------------------------------------------[0m
[1;31mTypeError[0m                                 Traceback (most recent call last)
[1;32m<ipython-input-5-0264b395553d>[0m in [0;36m<module>[1;34m[0m
[1;32m----> 1[1;33m [0mp[0m [1;33m=[0m [0mPunto2d[0m[1;33m([0m[1;36m100[0m[1;33m,[0m [1;36m10[0m[1;33m,[0m [1;36m3[0m[1;33m)[0m[1;33m[0m[1;33m[0m[0m
[0m
[1;31mTypeError[0m: __init__() takes 3 positional arguments but 4 were given
TypeError: __init__() takes 3 positional arguments but 4 were given

